Workbook
Name BaseBVPS: Valuation_Sensitivity!$C$4
Name BaseROE: Valuation_Sensitivity!$C$5
Name Beta: Control_Panel!$C$9
Name COE: Valuation_Sensitivity!$C$6
Name Depreciation: 'Income Statement (Cons-Stand)'!#REF!
Name Earning_Per_Share__Rs: 'Income Statement (Cons-Stand)'!#REF!
Name Employee_Cost: 'Income Statement (Cons-Stand)'!#REF!
Name Equity_Dividend: 'Income Statement (Cons-Stand)'!#REF!
Name Expenditure: 'Income Statement (Cons-Stand)'!#REF!
Name GDP_Growth: Control_Panel!#REF!
Name GDPGrowth: Control_Panel!$C$6
Name Growth: Valuation_Sensitivity!$C$7
Name Income: 'Income Statement (Cons-Stand)'!#REF!
Name Inflation: Control_Panel!$C$7
Name Interest_Earned: 'Income Statement (Cons-Stand)'!#REF!
Name Interest_expended: 'Income Statement (Cons-Stand)'!#REF!
Name JustifiedP_B: Valuation_Sensitivity!$C$8
Name Market_Premium: Control_Panel!$C$10
Name MarketPremium: Control_Panel!$C$10
Name Net_Profit_for_the_Year: 'Income Statement (Cons-Stand)'!#REF!
Name Operating_Expenses: 'Income Statement (Cons-Stand)'!#REF!
Name Other_Income: 'Income Statement (Cons-Stand)'!#REF!
Name Per_share_data__annualised: 'Income Statement (Cons-Stand)'!#REF!
Name Profit_brought_forward: 'Income Statement (Cons-Stand)'!#REF!
Name Provisions___Contingencies: 'Income Statement (Cons-Stand)'!#REF!
Name Risk_Free_Rate: Control_Panel!#REF!
Name Risk_FreeRate: Control_Panel!#REF!
Name RiskFreeRate: Control_Panel!$C$8
Name Selling__Admin___Misc_Expenses: 'Income Statement (Cons-Stand)'!#REF!
Name TargetPrice: Valuation_Sensitivity!$C$9
Name Total: 'Income Statement (Cons-Stand)'!#REF!
Name Total_Expenses: 'Income Statement (Cons-Stand)'!#REF!
Name Total_Income: 'Income Statement (Cons-Stand)'!#REF!

Sheet Equity Research
B1: HDFC BANK LIMITED | REPORT | FY21–FY30
B2: NSE: HDFCBANK · BSE: 500180 · Indian Private Banking Sector · Prepared: March 2025
B3: RATING | F3: TARGET PRICE | J3: LOAN CAGR | N3: FY30 ROE | R3: P/B JUSTIFIED
B4: HOLD | F4: =Valuation_Sensitivity!C9 -> 119.09691 | J4: ='Output (IC Memo Ready)'!C6 -> 0.16 | R4: =Valuation_Sensitivity!C8 -> 1.6256998
B6: 1. INVESTMENT THESIS | M6: Year | N6: FY21 | O6: FY22 | P6: FY23 | Q6: FY24 | R6: FY25
B7: Growth | E7: Loan book ~16% CAGR FY26–30; digital banking driving asset expansion | M7: Net Profit | N7: 31116 | O7: 36961 | P7: 44109 | Q7: 60811 | R7: 68000
B8: Profitability | E8: ROE recovery 9.3%→17.5%; NIM stable ~5.8% post-merger | M8: Revenue | N8: 80500 | O8: 99500 | P8: 120500 | Q8: 152000 | R8: 170000
B9: Capital | E9: CET1 >15%; well above RBI 11.5% requirement; capital buffer intact | M9: Loan Book | N9: 1131900 | O9: 1360000 | P9: 1600000 | Q9: 2481200 | R9: 2722000
B10: Valuation | E10: Stock near fair value at ₹119; accumulate below ₹100 for margin of safety | M10: ROE % | N10: 0.165 | O10: 0.169 | P10: 0.172 | Q10: 0.141 | R10: 0.13
B12: 4. HISTORICAL FINANCIALS (₹ Crores) FY21–FY25
B13: Metric | C13: FY21 | D13: FY22 | E13: FY23 | F13: FY24 | G13: FY25
B14: Net Interest Inc | C14: =Historical_Financials!C8 -> 69304.81 | D14: =Historical_Financials!D8 -> 77352.08 | E14: =Historical_Financials!E8 -> 92974.11 | F14: =Historical_Financials!F8 -> 129510.47 | G14: =Historical_Financials!G8 -> 152473.23
B15: Total Revenue | C15: =Historical_Financials!C10 -> 96637.69 | D15: =Historical_Financials!D10 -> 109111.07 | E15: =Historical_Financials!E10 -> 126886.16 | F15: =Historical_Financials!F10 -> 253856.22 | G15: =Historical_Financials!G10 -> 287021.73
B16: Net Profit | C16: =Historical_Financials!C13 -> 31856.76 | D16: =Historical_Financials!D13 -> 38150.9 | E16: =Historical_Financials!E13 -> 46148.7 | F16: =Historical_Financials!F13 -> 65446.5 | G16: =Historical_Financials!G13 -> 73440.17
B17: Loan Book | C17: =Historical_Financials!C19 -> 1185283.5 | D17: =Historical_Financials!D19 -> 1420942.3 | E17: =Historical_Financials!E19 -> 1661949.3 | F17: =Historical_Financials!F19 -> 2565891.4 | G17: =Historical_Financials!G19 -> 2724938.2
B18: ROE (%) | C18: =C16/Historical_Financials!C16 -> 0.1518361 | D18: =D16/Historical_Financials!D16 -> 0.15425339 | E18: =E16/Historical_Financials!E16 -> 0.15944271 | F18: =F16/Historical_Financials!F16 -> 0.14339873 | G18: =G16/Historical_Financials!G16 -> 0.14074677
B19: NIM (%) | C19: =Historical_Financials!C8/(Historical_Financials!C19+Historical_Financials!C20) -> 0.042672574 | D19: =Historical_Financials!D8/(Historical_Financials!D19+Historical_Financials!D20) -> 0.041360189 | E19: =Historical_Financials!E8/(Historical_Financials!E19+Historical_Financials!E20) -> 0.042775608 | F19: =Historical_Financials!F8/(Historical_Financials!F19+Historical_Financials!F20) -> 0.036261465 | G19: =Historical_Financials!G8/(Historical_Financials!G19+Historical_Financials!G20) -> 0.038981643
B20: GNPA (%) | C20: 0.0132 | D20: 0.0117 | E20: 0.0112 | F20: 0.0124 | G20: 0.013
B22: 5. FORECAST MODEL (₹ Crores) FY26–FY30
B23: Metric | C23: Metric | D23: Metric | E23: Metric | F23: Metric | G23: Metric
B24: Loan Book | C24: =Forecast_Model!C5 -> 3160928.3 | D24: =Forecast_Model!D5 -> 3666676.8 | E24: =Forecast_Model!E5 -> 4253345.1 | F24: =Forecast_Model!F5 -> 4933880.3 | G24: =Forecast_Model!G5 -> 5723301.1
B25: Net Income | C25: =Forecast_Model!C14 -> 48558.398 | D25: =Forecast_Model!D14 -> 66569.149 | E25: =Forecast_Model!E14 -> 89100.246 | F25: =Forecast_Model!F14 -> 111624.79 | G25: =Forecast_Model!G14 -> 135879.06
B26: ROE (%) | C26: =Forecast_Model!C15 -> 0.093061298 | D26: =Forecast_Model!D15 -> 0.1187386 | E26: =Forecast_Model!E15 -> 0.14514007 | F26: =Forecast_Model!F15 -> 0.16291508 | G26: =Forecast_Model!G15 -> 0.17544748
B27: NIM (%) | C27: =Control_Panel!$C$18 -> 0.058 | D27: =Control_Panel!$C$18 -> 0.058 | E27: =Control_Panel!$C$18 -> 0.058 | F27: =Control_Panel!$C$18 -> 0.058 | G27: =Control_Panel!$C$18 -> 0.058
B28: EPS (₹) | C28: =Forecast_Model!C19 -> 6.3451723 | D28: =Forecast_Model!D19 -> 8.6986545 | E28: =Forecast_Model!E19 -> 11.642814 | F28: =Forecast_Model!F19 -> 14.586118 | G28: =Forecast_Model!G19 -> 17.755447
B29: BV/Share (₹) | C29: =Valuation!E7 -> 73.258857 | D29: =Valuation!F7 -> 80.21778 | E29: =Valuation!G7 -> 89.532032 | F29: =Valuation!H7 -> 101.20093 | G29: =Valuation!I7 -> 115.40528
B31: Key Assumptions: Loan Growth 16% | NIM 5.8% | Cost of Equity 12.2% | Terminal Growth 5.0% | Tax 25.2%
B33: 6. VALUATION
B34: Model | F34: Residual Income Model (RIM)
B35: Intrinsic Equity Value (Cr) | F35: =Valuation!I25 -> 897393.24
B36: Intrinsic Value / Share | F36: =(F35*10)/'Capital_Raising Strategy'!C7 -> 1172.6323
B37: Justified P/B | F37: =Valuation_Sensitivity!C8 -> 1.6256998
B38: Book Value / Share | F38: =Valuation_Sensitivity!C4 -> 73.258857
B39: TARGET PRICE | F39: =F4 & " → HOLD" -> 119.096908842113 → HOLD
B41: 7. SENSITIVITY (Target Price ₹ — ROE vs COE)
B42: ROE↓/COE→ | C42: =Valuation_Sensitivity!C13 -> 0.11 | D42: =Valuation_Sensitivity!D13 -> 0.12 | E42: =Valuation_Sensitivity!E13 -> 0.13 | F42: =Valuation_Sensitivity!F13 -> 0.14
B43: =Valuation_Sensitivity!B14 -> 0.14 | C43: =Valuation_Sensitivity!C14 -> 113.19468 | D43: =Valuation_Sensitivity!D14 -> 95.788801 | E43: =Valuation_Sensitivity!E14 -> 83.022482 | F43: =Valuation_Sensitivity!F14 -> 73.258857
B44: =Valuation_Sensitivity!B16 -> 0.16 | C44: =Valuation_Sensitivity!C16 -> 139.81857 | D44: =Valuation_Sensitivity!D16 -> 118.31875 | E44: =Valuation_Sensitivity!E16 -> 102.54973 | F44: =Valuation_Sensitivity!F16 -> 90.48966
B45: =Valuation_Sensitivity!B18 -> 0.18 | C45: =Valuation_Sensitivity!C18 -> 166.44245 | D45: =Valuation_Sensitivity!D18 -> 140.84869 | E45: =Valuation_Sensitivity!E18 -> 122.07698 | F45: =Valuation_Sensitivity!F18 -> 107.72046
B47: 8. RISK ANALYSIS
...

Sheet Valuation_Sensitivity
B1: HDFC BANK LIMITED
A3: # | B3: Case
B4: BaseBVPS | C4: =Valuation!E7 -> 73.258857
B5: BaseROE (Terminal/Sustainable) | C5: =Valuation!I12 -> 0.16394218
B6: COE | C6: =Control_Panel!C11 -> 0.122
B7: Long-Term Book Growth | C7: =Control_Panel!C12 -> 0.054967566
B8: JustifiedP/B | C8: =(BaseROE-Growth)/(COE-Growth) -> 1.6256998
B9: TargetPrice | C9: =BaseBVPS*JustifiedP_B -> 119.09691
A13: # | B13: =C9 -> 119.09691 | C13: 0.11 | D13: 0.12 | E13: 0.13 | F13: 0.14
B14: 0.14 | C14: 113.19468 | D14: 95.788801 | E14: 83.022482 | F14: 73.258857
B15: 0.15 | C15: 126.50662 | D15: 107.05377 | E15: 92.786107 | F15: 81.874258
B16: 0.16 | C16: 139.81857 | D16: 118.31875 | E16: 102.54973 | F16: 90.48966
B17: 0.17 | C17: 153.13051 | D17: 129.58372 | E17: 112.31336 | F17: 99.105062
B18: 0.18 | C18: 166.44245 | D18: 140.84869 | E18: 122.07698 | F18: 107.72046
A21: # | B21: 3-Year Expected CAGR
B23: CMP Scenerios
B24: 100 | C24: =(TargetPrice/B24)^(1/3)-1 -> 0.059986083 | D24: =IF(B24>0.15,"Strong Moderate",IF(B24>0.08,"Moderate Upside",IF(B24>0.03,"Weak Upside",IF(B24>0,"Hold","Downside")))) -> Strong Moderate
B25: 110 | C25: =(TargetPrice/B25)^(1/3)-1 -> 0.026839582 | D25: =IF(B25>0.15,"Strong Moderate",IF(B25>0.08,"Moderate Upside",IF(B25>0.03,"Weak Upside",IF(B25>0,"Hold","Downside")))) -> Strong Moderate
B26: 120 | C26: =(TargetPrice/B26)^(1/3)-1 -> -0.002514906 | D26: =IF(B26>0.15,"Strong Moderate",IF(B26>0.08,"Moderate Upside",IF(B26>0.03,"Weak Upside",IF(B26>0,"Hold","Downside")))) -> Strong Moderate

Sheet Output (IC Memo Ready)
B1: HDFC BANK LIMITED
A3: # | B3: Investment Thesis
A5: # | B5: Growth
B6: Loan CAGR projected at (FY26-FY30) | C6: =Forecast_Model!G34 -> 0.16
B7: Balance Sheet expansion sustainable under CET1>13% | C7: =IF(Forecast_Model!C35>=Forecast_Model!C30,"Sustainable","Raise Required") -> Sustainable
B8: NIM compression manageable (-50bps)
A10: # | B10: Profitability
B11: Base ROE | C11: ='Risk & Sensitivity'!C6 -> 0.093061298
B12: Stress ROE (NIM-50 bps) | C12: ='Risk & Sensitivity'!D15 -> 0.071911003
B13: ROE Impact | C13: ='Risk & Sensitivity'!E15 -> -0.021150295
B14: Earning Decline Under Stress | C14: ='Risk & Sensitivity'!E14 -> -0.22727273
A16: # | B16: Capital
B17: Base CET1 | C17: ='Risk & Sensitivity'!C17 -> 0.13553582
B18: Stress CET1 | C18: ='Risk & Sensitivity'!D17 -> 0.14528233
A20: # | B20: Method | C20: Value per Share | D20: Weighting
A22: # | B22: Valuation Summary
B23: Intrinsic | C23: ='Risk & Sensitivity'!C7/'Capital_Raising Strategy'!C7 -> 117.26323 | D23: 0.5
B24: P/B Fair Value | C24: =Valuation!E9 -> 117.21417 | D24: 0.5
B25: TargetPrice | C25: =('Output (IC Memo Ready)'!C23*'Output (IC Memo Ready)'!D24)+('Output (IC Memo Ready)'!C24*'Output (IC Memo Ready)'!D23) -> 117.2387
A27: # | B27: Risk Factors
B28: Credit Shock | C28: Earning highly senesitive to asset liquidity deterioration
B29: Liquidity Tightening | C29: Valuation sensitive to margin compression
B30: Regulatory Capital | C30: Capital Policy changes can structurally reduce valuation
A32: #

Sheet Risk & Sensitivity
B1: HDFC BANK LIMITED
A3: # | B3: Case
B5: Metrics | C5: Value | D5: Interpration | F5: New NIM | G5: ='Risk & Sensitivity'!C9-0.005 -> 0.053
B6: ROE | C6: =Valuation!E18/Valuation!E17 -> 0.093061298 | D6: Moderate Profitability | F6: New NII | G6: =G5*Forecast_Model!C7 -> 155975.46
B7: Intrinsic Value | C7: =Valuation!I25 -> 897393.24 | D7: Fair Value Baseline | F7: Decline in NII | G7: =G6-Forecast_Model!C8 -> -14714.666
B8: CET1 | C8: =Investor_Positioning!D12 -> 0.13553582 | D8: Strong Capital Buffer | F8: Impact on NI | G8: =G7*(1-'Capital_Raising Strategy'!C11) -> -11036
B9: NIM | C9: =Forecast_Model!C8/Forecast_Model!C7 -> 0.058 | D9: Healthy Margin | F9: RWA | G9: =Forecast_Model!C18/'Risk & Sensitivity'!C8 -> 3849826.6
F10: New Equity | G10: =Forecast_Model!C18+'Risk & Sensitivity'!D14 -> 559311.79
A11: # | B11: Stress Case (NIM-50bps)
B13: Metrics | C13: Base | D13: Stress | E13: Change | F13: Interpreation
B14: Net Income | C14: =Forecast_Model!C14 -> 48558.398 | D14: =Forecast_Model!C14+'Risk & Sensitivity'!G8 -> 37522.398 | E14: =(D14-C14)/C14 -> -0.22727273 | F14: Earnings sensitive to NIM
B15: ROE | C15: =C6 -> 0.093061298 | D15: =D14/Forecast_Model!C18 -> 0.071911003 | E15: =D15-C6 -> -0.021150295 | F15: Profitability declines
B16: Intrinsic Value | C16: =C7 -> 897393.24 | D16: =C16*(D14/C14) -> 693440.23 | E16: =(D16-C16)/C16 -> -0.22727273 | F16: Valuation downside risk
B17: CET1 | C17: =C8 -> 0.13553582 | D17: =G10/G9 -> 0.14528233 | E17: =D17-C8 -> 0.0097465165 | F17: Capital remains strong
A19: # | B19: Sensitivity Score
B21: Risk Area | C21: Rating
B22: Earnings Sensitivvity | C22: Moderate
B23: Capital Risk | C23: Low
B24: Valuation Risk | C24: High

Sheet Investor_Positioning
B1: HDFC BANK LIMITED
A3: # | B3: Metrics | C3: Current | D3: Target | E3: Narrative
A5: # | B5: ROE | C5: =Forecast_Model!C15 -> 0.093061298 | D5: ='M&A_Strategy'!F29 -> 0.099332837 | E5: ROE improves post transaction; earnings accretive
B6: Growth Rate | C6: =Forecast_Model!D20 -> 0.37090909 | D6: ='M&A_Strategy'!F28 -> 0.041273107 | E6: Transaction enhances earnings growth trajectory
B7: Capital Adequacy | C7: =Forecast_Model!C30 -> 0.12 | D7: ='Risk & Sensitivity'!C8 -> 0.13553582 | E7: Capital position remains strong post-acquisition
B8: Leverage | C8: =Forecast_Model!C21 -> 9.6473079 | D8: ='M&A_Strategy'!F30 -> 10.304498 | E8: Balance sheet expansion manageable
B9: EPS | C9: =Forecast_Model!C19 -> 6.3451723 | D9: -
B10: Goodwill % of Equity | C10: ='M&A_Strategy'!C35 -> 0.036745159 | D10: -
B11: Debt Funding % | C11: - | D11: ='M&A_Strategy'!F9 -> 0.5 | E11: Balance funding structure with 50% debt and 50% equity; financial risk remains controlled
B12: CET1% | C12: =Forecast_Model!C30 -> 0.12 | D12: =('M&A_Strategy'!F12+'M&A_Strategy'!F19+'M&A_Strategy'!F7)/(Forecast_Model!C29+160000) -> 0.13553582

Sheet M&A_Strategy
B1: HDFC BANK LIMITED
A4: # | B4: Transaction Assumptions
B6: Acquirer Opening Equity | C6: =Forecast_Model!C18 -> 521789.39 | E6: Target NI | F6: 4000
B7: Acquirer Net income | C7: =Forecast_Model!C14 -> 48558.398 | E7: Target Equity | F7: 25000
B8: Shares O/s | C8: ='Capital_Raising Strategy'!C7 -> 7652.8099 | E8: Target Assets | F8: 200000
B9: Share Price | C9: =Valuation!E9 -> 117.21417 | E9: Debt % Funding | F9: 0.5
B10: Cost of Debt | C10: =Control_Panel!C12 -> 0.054967566 | E10: Equity % Funding | F10: 0.5
B11: Tax Rate | C11: =Control_Panel!C22 -> 0.25 | E11: Synergy % | F11: 0.05
B12: Base Assets | C12: =Forecast_Model!C28 -> 5408629.2 | E12: Base Equity | F12: =Forecast_Model!C17 -> 560636.11
B13: P/B | C13: 1.8
A16: # | B16: Sources & Uses | C16: INR (CR) | E16: Sources
B18: Purchase Price | C18: =F7*C13 -> 45000 | E18: Debt Raised | F18: =C18*F9 -> 22500
E19: Equity Raised | F19: =C18*F10 -> 22500
A21: # | B21: Pro Forma Financial Impact
B23: Shares Issued | C23: =F19/C9 -> 191.95631 | E23: Pro Forma NI | F23: =C7+F6+C27-C26 -> 51830.82
B24: Total Shares Post | C24: =C8+C23 -> 7844.7663 | E24: Pro Forma Equity | F24: =C6+F19 -> 544289.39
B25: Interest Expense | C25: =F18*C10 -> 1236.7702 | E25: Pro Forma Assets | F25: =C12+F8 -> 5608629.2
B26: After-Tax Interest | C26: =C25*(1-C11) -> 927.57767 | E26: EPS Pre | F26: =C7/C8 -> 6.3451723
B27: Synergy NI | C27: =F6*F11 -> 200 | E27: EPS Post | F27: =F23/C24 -> 6.6070573
E28: EPS Accretion % | F28: =(F27/F26)-1 -> 0.041273107
E29: ROE Post | F29: =F23/C6 -> 0.099332837
E30: Leverage Post | F30: =F25/F24 -> 10.304498
A32: # | B32: Goodwill & Capital Impact
B34: Goodwill | C34: =C18-F7 -> 20000 | E34: Tangible Equity | F34: =F24-C34 -> 524289.39
B35: Goodwill% of Equity | C35: =C34/F24 -> 0.036745159 | E35: Tangible ROE | F35: =F23/F34 -> 0.098859182
A41: #
A43: #
P50: Equity % Funding

Sheet Capital_Raising Strategy
B1: HDFC BANK LIMITED
A3: # | B3: BASE CASE HELPERS
B4: Base Equity | C4: =Forecast_Model!C18 -> 521789.39
B5: Base Net Income | C5: =Forecast_Model!C14 -> 48558.398
B6: Base ROE | C6: =C5/C4 -> 0.093061298
B7: Base Shares O/s | C7: =734440.17/95.97 -> 7652.8099
B8: Current Share Price | C8: =Valuation!E9 -> 117.21417
B9: Total Assets | C9: =Historical_Financials!G21 -> 4392417.4
B10: AT1 Int Rate | C10: =Control_Panel!C24 -> 0.09
B11: Tax Rate | C11: =Control_Panel!C22 -> 0.25
A13: # | B13: Scenario | C13: Equity Raise | D13: Debt Raise | E13: New Equity | F13: Interest Exp | G13: After-Tax Int | H13: Adj Net Income | I13: New Roe | J13: ROE Impact | K13: New Shares Issu | L13: Total Shares post Raise | M13: Dilution% | N13: New Leverage
A15: # | B15: Scenario 1: No Raise | C15: 0 | D15: 0 | E15: =$C$4+C15 -> 521789.39 | F15: =D15*Control_Panel!$C$24 -> 0 | G15: =F15*(1-$C$11) -> 0 | H15: =$C$5-G15 -> 48558.398 | I15: =H15/E15 -> 0.093061298 | J15: =I15-$C$6 -> 0 | K15: =C15/$C$8 -> 0 | L15: =$C$7+K15 -> 7652.8099 | M15: =K15/$C$7 -> 0 | N15: =C9/C4 -> 8.4179891
B16: Scenario 2: QIP | C16: 25500 | D16: 0 | E16: =$C$4+C16 -> 547289.39 | F16: =D16*Control_Panel!$C$24 -> 0 | G16: =F16*(1-$C$11) -> 0 | H16: =$C$5-G16 -> 48558.398 | I16: =H16/E16 -> 0.088725268 | J16: =I16-$C$6 -> -0.0043360298 | K16: =C16/$C$8 -> 217.55049 | L16: =$C$7+K16 -> 7870.3604 | M16: =K16/$C$7 -> 0.02842753 | N16: =C9/(C4+C16) -> 8.0257675
B17: Scenario 3: AT1 Bond | C17: 0 | D17: 25000 | E17: =$C$4+C17 -> 521789.39 | F17: =D17*Control_Panel!$C$24 -> 2250 | G17: =F17*(1-$C$11) -> 1687.5 | H17: =$C$5-G17 -> 46870.898 | I17: =H17/E17 -> 0.089827235 | J17: =I17-$C$6 -> -0.0032340635 | K17: =C17/$C$8 -> 0 | L17: =$C$7+K17 -> 7652.8099 | M17: =K17/$C$7 -> 0 | N17: =(C9+D17)/C4 -> 8.4659012
B18: Scenario 4: Hybrid Structure | C18: 12500 | D18: 12500 | E18: =$C$4+C18 -> 534289.39 | F18: =D18*Control_Panel!$C$24 -> 1125 | G18: =F18*(1-$C$11) -> 843.75 | H18: =$C$5-G18 -> 47714.648 | I18: =H18/E18 -> 0.089304877 | J18: =I18-$C$6 -> -0.0037564216 | K18: =C18/$C$8 -> 106.6424 | L18: =$C$7+K18 -> 7759.4523 | M18: =K18/$C$7 -> 0.013935064 | N18: =(C9+D18)/(C4+C18) -> 8.2444411

Sheet Valuation
B1: HDFC BANK LIMITED
A3: # | B3: Metrics | C3: Unit | D3: FY25 | E3: FY26E | F3: FY27E | G3: FY28E | H3: FY29E | I3: FY30E
A5: # | B5: Price to Book Model
B6: Current Book Value | C6: INR Cr | D6: =Historical_Financials!G16/'Balance Sheet (Cons-Stand)'!B9 -> 681.88154 | E6: - | F6: - | G6: - | H6: - | I6: -
B7: Forecast Book Value | C7: Per Share | D7: - | E7: =Forecast_Model!C17/'Capital_Raising Strategy'!$C$7 -> 73.258857 | F7: =Forecast_Model!D17/'Capital_Raising Strategy'!$C$7 -> 80.21778 | G7: =Forecast_Model!E17/'Capital_Raising Strategy'!$C$7 -> 89.532032 | H7: =Forecast_Model!F17/'Capital_Raising Strategy'!$C$7 -> 101.20093 | I7: =Forecast_Model!G17/'Capital_Raising Strategy'!$C$7 -> 115.40528
B8: Target P/B Multiple | D8: - | E8: =Control_Panel!$C$15 -> 1.6 | F8: =Control_Panel!$C$15 -> 1.6 | G8: =Control_Panel!$C$15 -> 1.6 | H8: =Control_Panel!$C$15 -> 1.6 | I8: =Control_Panel!$C$15 -> 1.6
B9: Implied Share Price | C9: Per Share | D9: - | E9: =E7*E8 -> 117.21417 | F9: =F7*F8 -> 128.34845 | G9: =G7*G8 -> 143.25125 | H9: =H7*H8 -> 161.92148 | I9: =I7*I8 -> 184.64845
A11: # | B11: Justified P/B Model
B12: ROE | D12: - | E12: - | F12: - | G12: - | H12: - | I12: =Forecast_Model!G14/AVERAGE(Forecast_Model!F17,Forecast_Model!G17) -> 0.16394218
B13: Cost to Equity | D13: - | E13: - | F13: - | G13: - | H13: - | I13: =Control_Panel!$C$11 -> 0.122
B14: Growth Rate | D14: - | E14: - | F14: - | G14: - | H14: - | I14: 0.05
A16: # | B16: Residual Income Model
B17: Opening Book Value | D17: - | E17: =Historical_Financials!G16 -> 521789.39 | F17: =Forecast_Model!C17 -> 560636.11 | G17: =Forecast_Model!D17 -> 613891.43 | H17: =Forecast_Model!E17 -> 685171.62 | I17: =Forecast_Model!F17 -> 774471.46
B18: Net Income | D18: - | E18: =Forecast_Model!C14 -> 48558.398 | F18: =Forecast_Model!D14 -> 66569.149 | G18: =Forecast_Model!E14 -> 89100.246 | H18: =Forecast_Model!F14 -> 111624.79 | I18: =Forecast_Model!G14 -> 135879.06
B19: Equity Charge | D19: - | E19: =E17*$I$13 -> 63658.306 | F19: =F17*$I$13 -> 68397.605 | G19: =G17*$I$13 -> 74894.754 | H19: =H17*$I$13 -> 83590.938 | I19: =I17*$I$13 -> 94485.518
B20: Residual Income | D20: - | E20: =E18-E19 -> -15099.908 | F20: =F18-F19 -> -1828.456 | G20: =G18-G19 -> 14205.492 | H20: =H18-H19 -> 28033.85 | I20: =I18-I19 -> 41393.546
B21: PV Factor | D21: - | E21: =1/(1+$I$13)^1 -> 0.8912656 | F21: =1/(1+$I$13)^2 -> 0.79435436 | G21: =1/(1+$I$13)^3 -> 0.70798072 | H21: =1/(1+$I$13)^4 -> 0.63099886 | I21: =1/(1+$I$13)^5 -> 0.56238757
B22: PV of Residual Income | D22: - | E22: =E20*E21 -> -13458.028 | F22: =F20*F21 -> -1452.442 | G22: =G20*G21 -> 10057.214 | H22: =H20*H21 -> 17689.327 | I22: =I20*I21 -> 23279.216
B23: Terminal Value | D23: - | E23: - | F23: - | G23: - | H23: - | I23: =I20*(1+I14)/(I13-I14) -> 603655.87
B24: PV of Terminal | D24: - | E24: - | F24: - | G24: - | H24: - | I24: =I23*I21 -> 339488.56
B25: Intrinsic Equity Value | D25: - | E25: - | F25: - | G25: - | H25: - | I25: =E17+(SUM(E22:I22)+I24) -> 897393.24

Sheet Forecast_Model
B1: HDFC BANK LIMITED
A3: # | B3: INR (Crores) | C3: FY26 | D3: FY27 | E3: FY28 | F3: FY29 | G3: FY30
B5: Project Loans | C5: =Historical_Financials!G19*(1+Control_Panel!$C$16) -> 3160928.3 | D5: =C5*(1+Control_Panel!$C$16) -> 3666676.8 | E5: =D5*(1+Control_Panel!$C$16) -> 4253345.1 | F5: =E5*(1+Control_Panel!$C$16) -> 4933880.3 | G5: =F5*(1+Control_Panel!$C$16) -> 5723301.1
B6: Project Deposits | C6: =Historical_Financials!G17*(1+Control_Panel!$C$17) -> 3090424 | D6: =C6*(1+Control_Panel!$C$17) -> 3523083.3 | E6: =D6*(1+Control_Panel!$C$17) -> 4016315 | F6: =E6*(1+Control_Panel!$C$17) -> 4578599.1 | G6: =F6*(1+Control_Panel!$C$17) -> 5219603
B7: Avg Loan Book | C7: =(Historical_Financials!G19+Forecast_Model!C5)/2 -> 2942933.2 | D7: =(C5+D5)/2 -> 3413802.5 | E7: =(D5+E5)/2 -> 3960010.9 | F7: =(E5+F5)/2 -> 4593612.7 | G7: =(F5+G5)/2 -> 5328590.7
B8: NII | C8: =C7*Control_Panel!$C$18 -> 170690.13 | D8: =D7*Control_Panel!$C$18 -> 198000.55 | E8: =E7*Control_Panel!$C$18 -> 229680.63 | F8: =F7*Control_Panel!$C$18 -> 266429.54 | G8: =G7*Control_Panel!$C$18 -> 309058.26
B9: Other Income | C9: =C7*2.2% -> 64744.531 | D9: =D7*2.2% -> 75103.656 | E9: =E7*2.2% -> 87120.24 | F9: =F7*2.2% -> 101059.48 | G9: =G7*2.2% -> 117229
B10: Total Income | C10: =C8+C9 -> 235434.66 | D10: =D8+D9 -> 273104.2 | E10: =E8+E9 -> 316800.87 | F10: =F8+F9 -> 367489.01 | G10: =G8+G9 -> 426287.26
B11: Operating Cost | C11: =C10*55% -> 129489.06 | D11: =D10*50% -> 136552.1 | E11: =E10*45% -> 142560.39 | F11: =F10*42% -> 154345.39 | G11: =G10*40% -> 170514.9 | H11: FY26 operating cost reflect post-merger initegration normalization and removal of one-off expenses from FY24-Fy25
B12: Provisions | C12: =C7*Control_Panel!$C$19 -> 41201.065 | D12: =D7*Control_Panel!$C$19 -> 47793.235 | E12: =E7*Control_Panel!$C$19 -> 55440.153 | F12: =F7*Control_Panel!$C$19 -> 64310.578 | G12: =G7*Control_Panel!$C$19 -> 74600.27
B13: PBT | C13: =C10-C11-C12 -> 64744.531 | D13: =D10-D11-D12 -> 88758.866 | E13: =E10-E11-E12 -> 118800.33 | F13: =F10-F11-F12 -> 148833.05 | G13: =G10-G11-G12 -> 181172.08
B14: Net Profit | C14: =C13*(1-Control_Panel!$C$22) -> 48558.398 | D14: =D13*(1-Control_Panel!$C$22) -> 66569.149 | E14: =E13*(1-Control_Panel!$C$22) -> 89100.246 | F14: =F13*(1-Control_Panel!$C$22) -> 111624.79 | G14: =G13*(1-Control_Panel!$C$22) -> 135879.06
B15: ROE | C15: =C14/C18 -> 0.093061298 | D15: =D14/D18 -> 0.1187386 | E15: =E14/E18 -> 0.14514007 | F15: =F14/F18 -> 0.16291508 | G15: =G14/G18 -> 0.17544748
B16: Retained Earnings | C16: =C14*(1-Control_Panel!$C$23) -> 38846.718 | D16: =D14*(1-Control_Panel!$C$23) -> 53255.319 | E16: =E14*(1-Control_Panel!$C$23) -> 71280.197 | F16: =F14*(1-Control_Panel!$C$23) -> 89299.831 | G16: =G14*(1-Control_Panel!$C$23) -> 108703.25
B17: Net Worth Update | C17: =Historical_Financials!G16+Forecast_Model!C16 -> 560636.11 | D17: =C17+D16 -> 613891.43 | E17: =D17+E16 -> 685171.62 | F17: =E17+F16 -> 774471.46 | G17: =F17+G16 -> 883174.71
B18: Opening Equity | C18: =Historical_Financials!G16 -> 521789.39 | D18: =C17 -> 560636.11 | E18: =D17 -> 613891.43 | F18: =E17 -> 685171.62 | G18: =F17 -> 774471.46
B19: EPS | C19: =C14/'Capital_Raising Strategy'!$C$7 -> 6.3451723 | D19: =D14/'Capital_Raising Strategy'!$C$7 -> 8.6986545 | E19: =E14/'Capital_Raising Strategy'!$C$7 -> 11.642814 | F19: =F14/'Capital_Raising Strategy'!$C$7 -> 14.586118 | G19: =G14/'Capital_Raising Strategy'!$C$7 -> 17.755447
B20: EPS Growth % | C20: - | D20: =(D19-C19)/(C19) -> 0.37090909 | E20: =(E19-D19)/(D19) -> 0.33846154 | F20: =(F19-E19)/(E19) -> 0.2528 | G20: =(G19-F19)/(F19) -> 0.21728395
B21: Leverage | C21: =C28/C17 -> 9.6473079 | D21: =D28/D17 -> 10.416667 | E21: =E28/E17 -> 10.416667 | F21: =F28/F17 -> 10.416667 | G21: =G28/G17 -> 10.416667
B22: Asset Growth% | C22: =(C28/Historical_Financials!G21)-1 -> 0.23135592 | D22: =(D28/C28)-1 -> 0.18231481 | E22: =(E28/D28)-1 -> 0.11611206 | F22: =(F28/E28)-1 -> 0.13033206 | G22: =(G28/F28)-1 -> 0.14035798
A24: # | B24: Balance Sheet Consistency
B25: Max Raw Supported | C25: =C17/Control_Panel!$C$26 -> 4671967.6 | D25: =D17/Control_Panel!$C$26 -> 5115761.9 | E25: =E17/Control_Panel!$C$26 -> 5709763.5 | F25: =F17/Control_Panel!$C$26 -> 6453928.8 | G25: =G17/Control_Panel!$C$26 -> 7359789.2
B26: Max Assets Supported | C26: =C25/Control_Panel!$C$25 -> 5839959.5 | D26: =D25/Control_Panel!$C$25 -> 6394702.4 | E26: =E25/Control_Panel!$C$25 -> 7137204.4 | F26: =F25/Control_Panel!$C$25 -> 8067411 | G26: =G25/Control_Panel!$C$25 -> 9199736.5
B27: Max Growth Allowed | C27: =C26/Historical_Financials!G21-1 -> 0.32955475 | D27: =D26/C28-1 -> 0.18231481 | E27: =E26/D28-1 -> 0.11611206 | F27: =F26/E28-1 -> 0.13033206 | G27: =G26/F28-1 -> 0.14035798
B28: Total Assets | C28: =MIN(Historical_Financials!G21*(1+'Key_Operating Drivers'!$C$5),Forecast_Model!C26) -> 5408629.2 | D28: =MIN(C28*(1+'Key_Operating Drivers'!$C$5),Forecast_Model!D26) -> 6394702.4 | E28: =MIN(D28*(1+'Key_Operating Drivers'!$C$5),Forecast_Model!E26) -> 7137204.4 | F28: =MIN(E28*(1+'Key_Operating Drivers'!$C$5),Forecast_Model!F26) -> 8067411 | G28: =MIN(F28*(1+'Key_Operating Drivers'!$C$5),Forecast_Model!G26) -> 9199736.5
B29: RWA | C29: =C28*Control_Panel!$C$25 -> 4326903.3 | D29: =D28*Control_Panel!$C$25 -> 5115761.9 | E29: =E28*Control_Panel!$C$25 -> 5709763.5 | F29: =F28*Control_Panel!$C$25 -> 6453928.8 | G29: =G28*Control_Panel!$C$25 -> 7359789.2
B30: Required CET1 % | C30: =Control_Panel!$C$26 -> 0.12 | D30: =Control_Panel!$C$26 -> 0.12 | E30: =Control_Panel!$C$26 -> 0.12 | F30: =Control_Panel!$C$26 -> 0.12 | G30: =Control_Panel!$C$26 -> 0.12
B31: Required Capital | C31: =C29*Control_Panel!$C$26 -> 519228.4 | D31: =D29*Control_Panel!$C$26 -> 613891.43 | E31: =E29*Control_Panel!$C$26 -> 685171.62 | F31: =F29*Control_Panel!$C$26 -> 774471.46 | G31: =G29*Control_Panel!$C$26 -> 883174.71
B32: Capital Surplus | C32: =C17-C31 -> 41407.708 | D32: =D17-D31 -> 0 | E32: =E17-E31 -> 0 | F32: =F17-F31 -> 0 | G32: =G17-G31 -> 0
B33: Equity Raise Needed | C33: =IF(C32<0,ABS(C32),0) -> 0 | D33: =IF(D32<0,ABS(D32),0) -> 0 | E33: =IF(E32<0,ABS(E32),0) -> 0 | F33: =IF(F32<0,ABS(F32),0) -> 0 | G33: =IF(G32<0,ABS(G32),0) -> 0
B34: Loan CAGR | C34: - | D34: - | E34: - | F34: - | G34: =(G5/C5)^(1/4)-1 -> 0.16
B35: Actual CET1 | C35: =C17/C29 -> 0.12956982 | D35: =D17/D29 -> 0.12 | E35: =E17/E29 -> 0.12 | F35: =F17/F29 -> 0.12 | G35: =G17/G29 -> 0.12

Sheet Key_Operating Drivers
B1: HDFC BANK LIMITED
A3: # | B3: Growth Metrics | C3: FY21-FY25
B4: Asset CAGR | C4: =(Historical_Financials!G21/Historical_Financials!C21)^(1/4)-1 -> 0.24993531
B5: Loan CAGR | C5: =(Historical_Financials!G19/Historical_Financials!C19)^(1/4)-1 -> 0.23135592
B6: Deposit CAGR | C6: =(Historical_Financials!G17/Historical_Financials!C17)^(1/4)-1 -> 0.19402128
B7: Net Profit CAGR | C7: =(Historical_Financials!G13/Historical_Financials!C13)^(1/4)-1 -> 0.23220514
B8: Equity CAGR | C8: =(Historical_Financials!G16/Historical_Financials!C16)^(1/4)-1 -> 0.25579042
B9: NII CAGR | C9: =(Historical_Financials!G8/Historical_Financials!C8)^(1/4)-1 -> 0.21788857
B11: INR (Crores) | C11: FY21 | D11: FY22 | E11: FY23 | F11: FY24 | G11: FY25
A13: # | B13: Profitability
B14: ROE | C14: - | D14: =Historical_Financials!D13/(AVERAGE(Historical_Financials!D16,Historical_Financials!C16)) -> 0.16691256 | E14: =Historical_Financials!E13/(AVERAGE(Historical_Financials!E16,Historical_Financials!D16)) -> 0.17195165 | F14: =Historical_Financials!F13/(AVERAGE(Historical_Financials!F16,Historical_Financials!E16)) -> 0.17549913 | G14: =Historical_Financials!G13/(AVERAGE(Historical_Financials!G16,Historical_Financials!F16)) -> 0.15015605
B15: ROA | C15: - | D15: =Historical_Financials!D13/AVERAGE(Historical_Financials!C21,Historical_Financials!D21) -> 0.019452632 | E15: =Historical_Financials!E13/AVERAGE(Historical_Financials!D21,Historical_Financials!E21) -> 0.019834542 | F15: =Historical_Financials!F13/AVERAGE(Historical_Financials!E21,Historical_Financials!F21) -> 0.019951295 | G15: =Historical_Financials!G13/AVERAGE(Historical_Financials!F21,Historical_Financials!G21) -> 0.017438812
B16: NIM | C16: - | D16: =Historical_Financials!D8/AVERAGE(Historical_Financials!D19,Historical_Financials!C19) -> 0.059359461 | E16: =Historical_Financials!E8/AVERAGE(Historical_Financials!E19,Historical_Financials!D19) -> 0.060316173 | F16: =Historical_Financials!F8/AVERAGE(Historical_Financials!F19,Historical_Financials!E19) -> 0.061265539 | G16: =Historical_Financials!G8/AVERAGE(Historical_Financials!G19,Historical_Financials!F19) -> 0.057636795
B17: Cost to Income | C17: =Historical_Financials!C11/Historical_Financials!C10 -> 0.36219057 | D17: =Historical_Financials!D11/Historical_Financials!D10 -> 0.36946233 | E17: =Historical_Financials!E11/Historical_Financials!E10 -> 0.40614114 | F17: =Historical_Financials!F11/Historical_Financials!F10 -> 0.59982513 | G17: =Historical_Financials!G11/Historical_Financials!G10 -> 0.61530209
A19: # | B19: Risk
B20: Loan to Deposit | C20: =Historical_Financials!C19/Historical_Financials!C17 -> 0.88870433 | D20: =Historical_Financials!D19/Historical_Financials!D17 -> 0.91202793 | E20: =Historical_Financials!E19/Historical_Financials!E17 -> 0.88276504 | F20: =Historical_Financials!F19/Historical_Financials!F17 -> 1.0795175 | G20: =Historical_Financials!G19/Historical_Financials!G17 -> 1.0051791
B21: Leverage Ratio | C21: =Historical_Financials!C21/Historical_Financials!C16 -> 8.5768315 | D21: =Historical_Financials!D21/Historical_Financials!D16 -> 8.5835409 | E21: =Historical_Financials!E21/Historical_Financials!E16 -> 8.7425867 | F21: =Historical_Financials!F21/Historical_Financials!F16 -> 8.8304912 | G21: =Historical_Financials!G21/Historical_Financials!G16 -> 8.4179891
B22: Provision Ratio | C22: =Historical_Financials!C12/Historical_Financials!C19 -> 0.025124512 | D22: =Historical_Financials!D12/Historical_Financials!D19 -> 0.021568603 | E22: =Historical_Financials!E12/Historical_Financials!E19 -> 0.017571998 | F22: =Historical_Financials!F12/Historical_Financials!F19 -> 0.014084922 | G22: =Historical_Financials!G12/Historical_Financials!G19 -> 0.013569662

Sheet Historical_Financials
B1: HDFC BANK LIMITED
A3: # | B3: INR (Crores) | C3: FY21 | D3: FY22 | E3: FY23 | F3: FY24 | G3: FY25
A5: # | B5: Income Statement
B6: Interest Income | C6: ='Income Statement (Cons-Stand)'!F8 -> 128552.39 | D6: ='Income Statement (Cons-Stand)'!E8 -> 135936.41 | E6: ='Income Statement (Cons-Stand)'!D8 -> 170754.05 | F6: ='Income Statement (Cons-Stand)'!C8 -> 283649.02 | G6: ='Income Statement (Cons-Stand)'!B8 -> 336367.43 | H6: Driven by loan book expansion and merger consolidation impact in FY24
B7: Interest Expense | C7: ='Income Statement (Cons-Stand)'!F12 -> 59247.58 | D7: ='Income Statement (Cons-Stand)'!E12 -> 58584.33 | E7: ='Income Statement (Cons-Stand)'!D12 -> 77779.94 | F7: ='Income Statement (Cons-Stand)'!C12 -> 154138.55 | G7: ='Income Statement (Cons-Stand)'!B12 -> 183894.2
B8: Net Interest Income | C8: =C6-C7 -> 69304.81 | D8: =D6-D7 -> 77352.08 | E8: =E6-E7 -> 92974.11 | F8: =F6-F7 -> 129510.47 | G8: =G6-G7 -> 152473.23 | H8: Reflects balance sheet growth; NIM broadly stable across period
B9: Other Income | C9: ='Income Statement (Cons-Stand)'!F9 -> 27332.88 | D9: ='Income Statement (Cons-Stand)'!E9 -> 31758.99 | E9: ='Income Statement (Cons-Stand)'!D9 -> 33912.05 | F9: ='Income Statement (Cons-Stand)'!C9 -> 124345.75 | G9: ='Income Statement (Cons-Stand)'!B9 -> 134548.5 | H9: Significant increase in FY24 due to merger-related consolidation and non-ccore income adj
B10: Total Income | C10: =C8+C9 -> 96637.69 | D10: =D8+D9 -> 109111.07 | E10: =E8+E9 -> 126886.16 | F10: =F8+F9 -> 253856.22 | G10: =G8+G9 -> 287021.73
B11: Operating Expense | C11: ='Income Statement (Cons-Stand)'!F16 -> 35001.26 | D11: ='Income Statement (Cons-Stand)'!E16 -> 40312.43 | E11: ='Income Statement (Cons-Stand)'!D16 -> 51533.69 | F11: ='Income Statement (Cons-Stand)'!C16 -> 152269.34 | G11: ='Income Statement (Cons-Stand)'!B16 -> 176605.07 | H11: Cost base normalized toward 1.4% by FY25
B12: Provisions & Contingencies | C12: ='Income Statement (Cons-Stand)'!F17 -> 29779.67 | D12: ='Income Statement (Cons-Stand)'!E17 -> 30647.74 | E12: ='Income Statement (Cons-Stand)'!D17 -> 29203.77 | F12: ='Income Statement (Cons-Stand)'!C17 -> 36140.38 | G12: ='Income Statement (Cons-Stand)'!B17 -> 36976.49 | H12: Credit cost normalized toward 1.4% by FY25
B13: Net Profit | C13: =C10-SUM(C11:C12) -> 31856.76 | D13: =D10-SUM(D11:D12) -> 38150.9 | E13: =E10-SUM(E11:E12) -> 46148.7 | F13: =F10-SUM(F11:F12) -> 65446.5 | G13: =G10-SUM(G11:G12) -> 73440.17 | H13: Strong growth trajectory;FY24 reflects merger uplift
A15: # | B15: Balance Sheet
B16: Net Worth | C16: ='Balance Sheet (Cons-Stand)'!F12 -> 209810.19 | D16: ='Balance Sheet (Cons-Stand)'!E12 -> 247326.17 | E16: ='Balance Sheet (Cons-Stand)'!D12 -> 289437.5 | F16: ='Balance Sheet (Cons-Stand)'!C12 -> 456395.25 | G16: ='Balance Sheet (Cons-Stand)'!B12 -> 521789.39 | H16: Step-up in FY24 reflects merger equity consolidation
B17: Deposits | C17: ='Balance Sheet (Cons-Stand)'!F13 -> 1333720.9 | D17: ='Balance Sheet (Cons-Stand)'!E13 -> 1558003 | E17: ='Balance Sheet (Cons-Stand)'!D13 -> 1882663.2 | F17: ='Balance Sheet (Cons-Stand)'!C13 -> 2376887.3 | G17: ='Balance Sheet (Cons-Stand)'!B13 -> 2710898.2 | H17: Growth aligned with asset expansion strategy
B18: Borrowings | C18: ='Balance Sheet (Cons-Stand)'!F14 -> 177696.75 | D18: ='Balance Sheet (Cons-Stand)'!E14 -> 226966.5 | E18: ='Balance Sheet (Cons-Stand)'!D14 -> 256548.66 | F18: ='Balance Sheet (Cons-Stand)'!C14 -> 730615.46 | G18: ='Balance Sheet (Cons-Stand)'!B14 -> 634605.57 | H18: Temporary spike in FY24; normalized in FY25
B19: Advances | C19: ='Balance Sheet (Cons-Stand)'!F27 -> 1185283.5 | D19: ='Balance Sheet (Cons-Stand)'!E27 -> 1420942.3 | E19: ='Balance Sheet (Cons-Stand)'!D27 -> 1661949.3 | F19: ='Balance Sheet (Cons-Stand)'!C27 -> 2565891.4 | G19: ='Balance Sheet (Cons-Stand)'!B27 -> 2724938.2 | H19: Core loan book growth; major driver of earnings expansion
B20: Investments | C20: ='Balance Sheet (Cons-Stand)'!F28 -> 438823.11 | D20: ='Balance Sheet (Cons-Stand)'!E28 -> 449263.86 | E20: ='Balance Sheet (Cons-Stand)'!D28 -> 511581.71 | F20: ='Balance Sheet (Cons-Stand)'!C28 -> 1005681.6 | G20: ='Balance Sheet (Cons-Stand)'!B28 -> 1186472.9 | H20: Increase reflects treasury and liquidty positioning post-merger
B21: Total Assets | C21: ='Balance Sheet (Cons-Stand)'!F32 -> 1799506.6 | D21: ='Balance Sheet (Cons-Stand)'!E32 -> 2122934.3 | E21: ='Balance Sheet (Cons-Stand)'!D32 -> 2530432.4 | F21: ='Balance Sheet (Cons-Stand)'!C32 -> 4030194.3 | G21: ='Balance Sheet (Cons-Stand)'!B32 -> 4392417.4 | H21: Balance sheet scale nearly doubled post-merger (FY24)
A23: # | B23: Cash Flow
B24: CFO | C24: ='Cash Flow Statement (Cons-Stand'!F8 -> 42476.46 | D24: ='Cash Flow Statement (Cons-Stand'!E8 -> -11959.57 | E24: ='Cash Flow Statement (Cons-Stand'!D8 -> 20813.7 | F24: ='Cash Flow Statement (Cons-Stand'!C8 -> 19069.34 | G24: ='Cash Flow Statement (Cons-Stand'!B8 -> 127241.84 | H24: Strong operating cash generation; typical banking model dynamics
B25: CFI | C25: ='Cash Flow Statement (Cons-Stand'!F9 -> -1680.87 | D25: ='Cash Flow Statement (Cons-Stand'!E9 -> -2216.33 | E25: ='Cash Flow Statement (Cons-Stand'!D9 -> -3423.89 | F25: ='Cash Flow Statement (Cons-Stand'!C9 -> 5313.77 | G25: ='Cash Flow Statement (Cons-Stand'!B9 -> -3850.64
B26: CFF | C26: ='Cash Flow Statement (Cons-Stand'!F10 -> -7321.35 | D26: ='Cash Flow Statement (Cons-Stand'!E10 -> 48124.02 | E26: ='Cash Flow Statement (Cons-Stand'!D10 -> 23940.56 | F26: ='Cash Flow Statement (Cons-Stand'!C10 -> -3983.06 | G26: ='Cash Flow Statement (Cons-Stand'!B10 -> -102477.54 | H26: Reflects dividend payments and funding adjustments
B27: Net Cash Change | C27: =SUM(C24:C26) -> 33474.24 | D27: =SUM(D24:D26) -> 33948.12 | E27: =SUM(E24:E26) -> 41330.37 | F27: =SUM(F24:F26) -> 20400.05 | G27: =SUM(G24:G26) -> 20913.66
B28: Non-cash Adj. | C28: -141.82 | D28: 165.1 | E28: 431.71 | F28: 11286.65 | G28: 199.73
A30: # | B30: Historical Summary Observations
B31: FY24 structural break due to merger
B32: ROE dilution post-merger
B33: Margin stable but cost structure expanded
B34: Leverage remained controlled

Sheet Control_Panel
B1: HDFC BANK LIMITED
A3: # | B3: INR (Crores) | C3: Base Case | D3: Notes
A5: # | B5: Assumptions
B6: GDPGrowth | C6: 0.065 | D6: RBI/IMF India forecast
B7: Inflation | C7: 0.05 | D7: RBI Target band
B8: RiskFreeRate | C8: 0.065 | D8: 10-year GOI bond yield
B9: Beta | C9: 0.8
B10: MarketPremium | C10: 0.07125
B11: CostofEquity | C11: =RiskFreeRate+(Beta*MarketPremium) -> 0.122
B12: Cost of Debt | C12: ='Income Statement (Cons-Stand)'!B12/'Balance Sheet (Cons-Stand)'!B15 -> 0.054967566
B13: Terminal Growth | C13: 0.045
B14: Target ROE | C14: 0.0931
B15: Target P/B | C15: 1.6
B16: Loan Growth % | C16: 0.16
B17: Deposit Growth % | C17: 0.14
B18: NIM % | C18: 0.058
B19: Credit Cost % | C19: 0.014
B20: Net Interest Income | C20: ='Income Statement (Cons-Stand)'!B8-'Income Statement (Cons-Stand)'!B12 -> 152473.23
B21: Avg Advances | C21: =('Balance Sheet (Cons-Stand)'!C27+'Balance Sheet (Cons-Stand)'!B27)/2 -> 2645414.8
B22: Tax Rate | C22: 0.25
B23: Payout | C23: 0.2
B24: AT1 Rate | C24: 0.09
B25: Risk Weight % | C25: 0.8
B26: Targer CET1 | C26: 0.12

Sheet Balance Sheet (Cons-Stand)
A1: HDFC BANK LIMITED
A2: Consolidated Balance Sheet | B2: ------------------- in Rs. Cr. -------------------
B3: Mar '25 | C3: Mar '24 | D3: Mar '23 | E3: Mar '22 | F3: Mar '21
B5: 12 mths | C5: 12 mths | D5: 12 mths | E5: 12 mths | F5: 12 mths
A7: Capital and Liabilities:
A8: Total Share Capital | B8: 765.22 | C8: 759.69 | D8: 557.97 | E8: 554.55 | F8: 551.28
A9: Equity Share Capital | B9: 765.22 | C9: 759.69 | D9: 557.97 | E9: 554.55 | F9: 551.28
A10: Employee Stock Opiton | B10: 3805.19 | C10: 2652.72 | D10: 0 | E10: 0 | F10: 0
A11: Reserves | B11: 517218.98 | C11: 452982.84 | D11: 288879.53 | E11: 246771.62 | F11: 209258.91
A12: Net Worth | B12: 521789.39 | C12: 456395.25 | D12: 289437.5 | E12: 247326.17 | F12: 209810.19
A13: Deposits | B13: 2710898.2 | C13: 2376887.3 | D13: 1882663.2 | E13: 1558003 | F13: 1333720.9
A14: Borrowings | B14: 634605.57 | C14: 730615.46 | D14: 256548.66 | E14: 226966.5 | F14: 177696.75
A15: Total Debt | B15: 3345503.8 | C15: 3107502.7 | D15: 2139211.9 | E15: 1784969.5 | F15: 1511417.6
A16: Minority Interest | B16: 16359.04 | C16: 13383.4 | D16: 860.26 | E16: 720.41 | F16: 632.76
A17: Policy Holders Funds | B17: 320601.53 | C17: 278080.8 | D17: 0 | E17: 0 | F17: 0
A18: Other Liabilities & Provisions | B18: 188163.66 | C18: 174832.07 | D18: 100922.77 | E18: 89918.19 | F18: 77646.07
A19: Total Liabilities | B19: 4392417.4 | C19: 4030194.3 | D19: 2530432.4 | E19: 2122934.3 | F19: 1799506.6
B20: Mar '25 | C20: Mar '24 | D20: Mar '23 | E20: Mar '22 | F20: Mar '21
B22: 12 mths | C22: 12 mths | D22: 12 mths | E22: 12 mths | F22: 12 mths
A24: Assets
A25: Cash & Balances with RBI | B25: 144390.25 | C25: 178718.67 | D25: 117189.28 | E25: 130030.71 | F25: 97370.36
A26: Balance with Banks, Money at Call | B26: 105557.65 | C26: 50115.84 | D26: 79958.53 | E26: 25355.02 | F26: 23902.17
A27: Advances | B27: 2724938.2 | C27: 2565891.4 | D27: 1661949.3 | E27: 1420942.3 | F27: 1185283.5
A28: Investments | B28: 1186472.9 | C28: 1005681.6 | D28: 511581.71 | E28: 449263.86 | F28: 438823.11
A29: Gross Block | B29: 15257.94 | C29: 12603.76 | D29: 8431.35 | E29: 6432.07 | F29: 5099.56
A30: Net Block | B30: 15257.94 | C30: 12603.76 | D30: 8431.35 | E30: 6432.07 | F30: 5099.56
A31: Other Assets | B31: 215800.53 | C31: 217182.95 | D31: 151322.28 | E31: 90910.36 | F31: 49027.92
A32: Total Assets | B32: 4392417.4 | C32: 4030194.3 | D32: 2530432.4 | E32: 2122934.3 | F32: 1799506.6
A34: Contingent Liabilities | B34: 2780601.4 | C34: 2409820.6 | D34: 1822393.4 | E34: 1457165.7 | F34: 1020028.8
A35: Book Value (Rs) | B35: 676.91 | C35: 597.27 | D35: 518.73 | E35: 445.99 | F35: 380.59

Sheet Cash Flow Statement (Cons-Stand
A1: HDFC BANK LIMITED
A2: Consolidated Cash Flow | B2: ------------------- in Rs. Cr. -------------------
B3: Mar '25 | C3: Mar '24 | D3: Mar '23 | E3: Mar '22 | F3: Mar '21
B5: 12 mths | C5: 12 mths | D5: 12 mths | E5: 12 mths | F5: 12 mths
A7: Net Profit Before Tax | B7: 93594.13 | C7: 75184.14 | D7: 61346.8 | E7: 50775.24 | F7: 42772.58
A8: Net Cash From Operating Activities | B8: 127241.84 | C8: 19069.34 | D8: 20813.7 | E8: -11959.57 | F8: 42476.46
A9: Net Cash (used in)/from Investing Activities | B9: -3850.64 | C9: 5313.77 | D9: -3423.89 | E9: -2216.33 | F9: -1680.87
A10: Net Cash (used in)/from Financing Activities | B10: -102477.54 | C10: -3983.06 | D10: 23940.56 | E10: 48124.02 | F10: -7321.35
A11: Net (decrease)/increase In Cash and Cash Equivalents | B11: 21113.39 | C11: 31686.7 | D11: 41762.08 | E11: 34113.22 | F11: 33332.41
A12: Opening Cash & Cash Equivalents | B12: 228834.51 | C12: 197147.81 | D12: 155385.73 | E12: 121272.51 | F12: 87940.11
A13: Closing Cash & Cash Equivalents | B13: 249947.9 | C13: 228834.51 | D13: 197147.81 | E13: 155385.73 | F13: 121272.53

Sheet Income Statement (Cons-Stand)
A1: HDFC BANK LIMITED
A2: Consolidated Profit & Loss account | B2: ------------------- in Rs. Cr. -------------------
B3: Mar '25 | C3: Mar '24 | D3: Mar '23 | E3: Mar '22 | F3: Mar '21
B5: 12 mths | C5: 12 mths | D5: 12 mths | E5: 12 mths | F5: 12 mths
A7: Income
A8: Interest Earned | B8: 336367.43 | C8: 283649.02 | D8: 170754.05 | E8: 135936.41 | F8: 128552.39
A9: Other Income | B9: 134548.5 | C9: 124345.75 | D9: 33912.05 | E9: 31758.99 | F9: 27332.88
A10: Total Income | B10: 470915.93 | C10: 407994.77 | D10: 204666.1 | E10: 167695.4 | F10: 155885.27
A11: Expenditure
A12: Interest expended | B12: 183894.2 | C12: 154138.55 | D12: 77779.94 | E12: 58584.33 | F12: 59247.58
A13: Employee Cost | B13: 34135.75 | C13: 31023 | D13: 20016.85 | E13: 15897.03 | F13: 13676.67
A14: Selling, Admin & Misc Expenses | B14: 175640.58 | C14: 154294.64 | D14: 58375.14 | E14: 53382.41 | F14: 49719.25
A15: Depreciation | B15: 3805.23 | C15: 3092.08 | D15: 2345.47 | E15: 1680.73 | F15: 1385.01
A16: Operating Expenses | B16: 176605.07 | C16: 152269.34 | D16: 51533.69 | E16: 40312.43 | F16: 35001.26
A17: Provisions & Contingencies | B17: 36976.49 | C17: 36140.38 | D17: 29203.77 | E17: 30647.74 | F17: 29779.67
A18: Total Expenses | B18: 397475.76 | C18: 342548.27 | D18: 158517.4 | E18: 129544.5 | F18: 124028.51
B19: Mar '25 | C19: Mar '24 | D19: Mar '23 | E19: Mar '22 | F19: Mar '21
B21: 12 mths | C21: 12 mths | D21: 12 mths | E21: 12 mths | F21: 12 mths
A23: Net Profit for the Year | B23: 73440.17 | C23: 65446.5 | D23: 46148.7 | E23: 38150.9 | F23: 31856.77
A24: Minority Interest | B24: 2647.92 | C24: 1384.46 | D24: 151.59 | E24: 98.15 | F24: 23.56
A25: Net P/L After Minority Interest & Share Of Associates | B25: 70792.25 | C25: 64062.04 | D25: 45997.11 | E25: 38052.75 | F25: 31833.21
A26: Profit brought forward | B26: 150045.57 | C26: 123939.45 | D26: 99062.77 | E26: 78594.2 | F26: 61817.69
A27: Total | B27: 223485.74 | C27: 189385.95 | D27: 145211.47 | E27: 116745.1 | F27: 93674.46
A28: Equity Dividend | B28: 0 | C28: 8404.42 | D28: 0 | E28: 0 | F28: 0
A29: Per share data (annualised)
A30: Earning Per Share (Rs) | B30: 95.97 | C30: 86.15 | D30: 82.71 | E30: 68.8 | F30: 57.79
A31: Book Value (Rs) | B31: 676.91 | C31: 597.27 | D31: 518.73 | E31: 445.99 | F31: 380.59
A32: Appropriations
A33: Transfer to Statutory Reserves | B33: 35410.53 | C33: 23470.27 | D33: 20279.66 | E33: 13888.04 | F33: 11945.05
A34: Transfer to Other Reserves | B34: 6734.74 | C34: 6081.23 | D34: 4410.87 | E34: 3696.14 | F34: 3111.65
A35: Proposed Dividend/Transfer to Govt | B35: 0 | C35: 8404.42 | D35: 0 | E35: 0 | F35: 0
A36: Balance c/f to Balance Sheet | B36: 178692.55 | C36: 150045.57 | D36: 120369.35 | E36: 99062.77 | F36: 78594.2
A37: Total | B37: 220837.82 | C37: 188001.49 | D37: 145059.88 | E37: 116646.95 | F37: 93650.9
